Workbook

Sheet Допущения
A1: ДОПУЩЕНИЯ МОДЕЛИ — меняй жёлтые ячейки, всё остальное пересчитается само
A3: Параметр | B3: Значение | C3: Ед. | D3: Комментарий
A4: Целевая выручка клиники | B4: 2300000 | C4: ₽/мес | D4: Настина цель: держать примерно на этом уровне, но за счёт другого состава — меньше Эльвиры, больше остальных
A5: База выручки — Остальные мастера (среднее июнь-июль) | B5: 960140 | C5: ₽/мес | D5: От этой базы считается рост
A6: Рост — Остальные, Сценарий А (медленный) | B6: 0.1 | C6: %/мес | D6: Настин ориентир: 10-20% в месяц — нижняя граница
A7: Рост — Остальные, Сценарий Б (быстрый) | B7: 0.2 | C7: %/мес | D7: Настин ориентир: 10-20% в месяц — верхняя граница
A8: Переменные расходы, % от выручки | B8: 0.493 | C8: % | D8: Среднее «Прямые расходы» / Выручка за июнь-июль из твоего П&Л (материалы + ЗП мастеров)
A9: Постоянные расходы | B9: 724000 | C9: ₽/мес | D9: «Косвенные расходы» июнь-июль БЕЗ закупки косметики (аренда, ФОТ офиса, IT, банк/налоги)
A10: Закупка косметики на продажу (сглажено) | B10: 134438 | C10: ₽/мес | D10: (Сумма закупок янв-авг) / 8 — временное решение, см. лист «Косметика — методология»

Sheet Эльвира vs Остальные
A1: Выручка по мастерам факт 2026 — из YClients-пайплайна, сумма = общая выручка
A2: Статья | B2: Январь | C2: Февраль | D2: Март | E2: Апрель | F2: Май | G2: Июнь | H2: Июль | I2: Август*
A3: Эльвира Аминева | B3: 834346 | C3: 990234 | D3: 945727 | E3: 991701 | F3: 1654863 | G3: 1374673 | H3: 1306050 | I3: 712840
A4: Остальные мастера (Татьяна, Александра, Влада, Анжела и т.д.) | B4: 601390 | C4: 591758 | D4: 1002318 | E4: 917482 | F4: 1174270 | G4: 966824 | H4: 953455 | I4: 490195
A5: Итого (= общая выручка) | B5: =B3+B4 | C5: =C3+C4 | D5: =D3+D4 | E5: =E3+E4 | F5: =F3+F4 | G5: =G3+G4 | H5: =H3+H4 | I5: =I3+I4
A6: Доля Эльвиры, % | B6: =B3/B5 | C6: =C3/C5 | D6: =D3/D5 | E6: =E3/E5 | F6: =F3/F5 | G6: =G3/G5 | H6: =H3/H5 | I6: =I3/I5
A8: * Август — не закрытый месяц (данные по 24.08).

Sheet П&Л факт 2026
A1: П&Л факт — из выгрузки Adesk (2026-08-21), без изменений
A2: Статья | B2: Январь | C2: Февраль | D2: Март | E2: Апрель | F2: Май | G2: Июнь | H2: Июль | I2: Август*
A3: Выручка | B3: 607057 | C3: 711918 | D3: 1949364 | E3: 1451132 | F3: 2657327 | G3: 2417021 | H3: 2389851 | I3: 1130940
A4: Прямые расходы (переменные) | B4: -422251 | C4: -425170 | D4: -1120269 | E4: -739891 | F4: -1556820 | G4: -1096289 | H4: -1274531 | I4: -133291
A5: в т.ч. Расходные материалы | B5: -84976 | C5: -117700 | D5: -729571 | E5: -333935 | F5: -920919 | G5: -551863 | H5: -581642 | I5: -108291
A6: в т.ч. ФОТ специалистов | B6: -337275 | C6: -307470 | D6: -390698 | E6: -405956 | F6: -635901 | G6: -544426 | H6: -692889 | I6: -25000
A7: Валовая прибыль | B7: 184806 | C7: 286748 | D7: 829095 | E7: 711241 | F7: 1100507 | G7: 1320732 | H7: 1115320 | I7: 997649
A8: Косвенные расходы (постоянные+прочее) | B8: -282741 | C8: -444671 | D8: -942541 | E8: -621197 | F8: -691519 | G8: -1258711 | H8: -883135 | I8: -523122
A9: в т.ч. Закупка косметики на продажу | B9: 0 | C9: 0 | D9: -298880 | E9: 0 | F9: -38430 | G9: -503954 | H9: -189243 | I9: -45000
A10: Операционная прибыль | B10: -97935 | C10: -157923 | D10: -113446 | E10: 90044 | F10: 408989 | G10: 62021 | H10: 232184 | I10: 474527
A11: Чистая прибыль | B11: -104220 | C11: -158413 | D11: -117900 | E11: 100219 | F11: 408989 | G11: -3026 | H11: 229184 | I11: 444092
A12: * Август — не закрытый месяц, не показатель за полный месяц.

Sheet Драйверы YClients
A1: Операционные драйверы — из YClients-пайплайна дашборда (не из Adesk)
A2: Метрика | B2: Январь | C2: Февраль | D2: Март | E2: Апрель | F2: Май | G2: Июнь | H2: Июль | I2: Август*
A3: Клиенты пришедшие (статус «Пришёл») | B3: 153 | C3: 172 | D3: 218 | E3: 202 | F3: 227 | G3: 211 | H3: 180 | I3: 124
A4: Услуги оказанные (статус «Пришёл») | B4: 293 | C4: 308 | D4: 378 | E4: 346 | F4: 422 | G4: 428 | H4: 348 | I4: 209
A5: Визиты (все подтверждённые записи, вкл. будущие в открытом месяце) | B5: 219 | C5: 255 | D5: 330 | E5: 304 | F5: 358 | G5: 372 | H5: 273 | I5: 181
A6: ВЫРУЧКА ОБЩАЯ, ₽ | B6: 1435736 | C6: 1581992 | D6: 1948045 | E6: 1909183 | F6: 2829133 | G6: 2341497 | H6: 2259505 | I6: 1203035
A7: в т.ч. Услуги | B7: 1212618 | C7: 1331622 | D7: 1573726 | E7: 1628494 | F7: 2302329 | G7: 1877362 | H7: 1715314 | I7: 982793
A8: в т.ч. Товары (косметика) | B8: 95533 | C8: 106620 | D8: 194119 | E8: 126539 | F8: 210004 | G8: 317235 | H8: 311391 | I8: 146542
A9: в т.ч. Абонементы | B9: 102985 | C9: 102750 | D9: 106700 | E9: 139150 | F9: 41700 | G9: 113400 | H9: 62100 | I9: 66410
A10: в т.ч. Депозиты (пополнения счёта) | B10: 4100 | C10: 41000 | D10: 31500 | E10: 0 | F10: 253100 | G10: 28500 | H10: 145700 | I10: 7290
A11: в т.ч. Сертификаты | B11: 20500 | C11: 0 | D11: 42000 | E11: 15000 | F11: 22000 | G11: 5000 | H11: 25000 | I11: 0
A12: Средний чек по клинике (выручка общая / визиты) | B12: =B6/B5 | C12: =C6/C5 | D12: =D6/D5 | E12: =E6/E5 | F12: =F6/F5 | G12: =G6/G5 | H12: =H6/H5 | I12: =I6/I5
A13: Средний чек по услугам (выручка услуги/ кол-во услуг) | B13: =B7/B4 | C13: =C7/C4 | D13: =D7/D4 | E13: =E7/E4 | F13: =F7/F4 | G13: =G7/G4 | H13: =H7/H4 | I13: =I7/I4
A14: Средний чек на клиента (выручка общая/ кол-во уклиентов) | B14: =B6/B3 | C14: =C6/C3 | D14: =D6/D3 | E14: =E6/E3 | F14: =F6/F3 | G14: =G6/G3 | H14: =H6/H3 | I14: =I6/I3
A15: Скидки, ₽ | B15: 136195 | C15: 175920 | D15: 301753 | E15: 201196 | F15: 345195 | G15: 365857 | H15: 170476 | I15: 81317
A16: Скидки, % от услуг | B16: =B15/B7 | C16: =C15/C7 | D16: =D15/D7 | E16: =E15/E7 | F16: =F15/F7 | G16: =G15/G7 | H16: =H15/H7 | I16: =I15/I7
A17: Потерянные клиенты (>90 дней) | B17: 484 | C17: 518 | D17: 539 | E17: 537 | F17: 565 | G17: 618 | H17: 683 | I17: 740
A19: * Август — партиал месяц (данные по 24.08), включает уже подтверждённые будущие записи в «Визиты», но НЕ в «Клиенты/услуги пришедшие» (эти двое — только фактически отработанные, статус «Пришёл»).
A21: Средний чек по услугам считаю так: выручка по услугам (кассовая, «Оказание услуг») / кол-во ПРИШЕДШИХ визитов (не всех подтверждённых). Это точнее, чем делить на все визиты (включая ещё не наступившие) — иначе для текущего месяца средний чек занижается искусственно, пока не все записи отработаны. Вариант «выручка/кол-во услуг» тоже возможен, но тогда мультиуслуговый визит (например чистка+пилинг) размывает чек на единицу услуги, а не показывает, сколько в среднем платит клиент за приход — решила, что по визиту нагляднее.

Sheet Загрузка мастеров
A1: Загрузка мастеров июнь-август 2026 — открыто по расписанию / записано / реально пришло vs открытое время
A3: Мастер | B3: Месяц | C3: Открыто, ч | D3: Записано, ч | E3: % записано | F3: Пришло, ч | G3: % пришло | H3: ср пришло | I3: разница записалось/пришло
A4: Александра | B4: Июнь | C4: 57.8 | D4: 44.3 | E4: =IF(C4=0,"—",D4/C4) | F4: 40.3 | G4: =IF(C4=0,"—",F4/C4) | H4: =AVERAGE(G4:G6) | I4: =F4/D4-1
A5: Александра | B5: Июль | C5: 41 | D5: 34.2 | E5: =IF(C5=0,"—",D5/C5) | F5: 31.9 | G5: =IF(C5=0,"—",F5/C5) | I5: =F5/D5-1
A6: Александра | B6: Август* | C6: 36.5 | D6: 34 | E6: =IF(C6=0,"—",D6/C6) | F6: 18.8 | G6: =IF(C6=0,"—",F6/C6) | I6: =F6/D6-1
A7: Эльвира Аминева | B7: Июнь | C7: 57.7 | D7: 122.9 | E7: =IF(C7=0,"—",D7/C7) | F7: 95.8 | G7: =IF(C7=0,"—",F7/C7) | H7: =AVERAGE(G8:G9) | I7: =F7/D7-1
A8: Эльвира Аминева | B8: Июль | C8: 93.1 | D8: 86.6 | E8: =IF(C8=0,"—",D8/C8) | F8: 77 | G8: =IF(C8=0,"—",F8/C8) | I8: =F8/D8-1
A9: Эльвира Аминева | B9: Август* | C9: 76.6 | D9: 75.9 | E9: =IF(C9=0,"—",D9/C9) | F9: 51.7 | G9: =IF(C9=0,"—",F9/C9) | I9: =F9/D9-1
A10: Анна | B10: Июнь | C10: 176.2 | D10: 71.6 | E10: =IF(C10=0,"—",D10/C10) | F10: 51.1 | G10: =IF(C10=0,"—",F10/C10) | H10: =AVERAGE(G10:G12) | I10: =F10/D10-1
A11: Анна | B11: Июль | C11: 157.8 | D11: 41.3 | E11: =IF(C11=0,"—",D11/C11) | F11: 34.8 | G11: =IF(C11=0,"—",F11/C11) | I11: =F11/D11-1
A12: Анна | B12: Август* | C12: 46.8 | D12: 15.5 | E12: =IF(C12=0,"—",D12/C12) | F12: 11.8 | G12: =IF(C12=0,"—",F12/C12) | I12: =F12/D12-1
A13: Влада | B13: Июнь | C13: 126.5 | D13: 90.8 | E13: =IF(C13=0,"—",D13/C13) | F13: 73.5 | G13: =IF(C13=0,"—",F13/C13) | H13: =AVERAGE(G13:G15) | I13: =F13/D13-1
A14: Влада | B14: Июль | C14: 86 | D14: 55 | E14: =IF(C14=0,"—",D14/C14) | F14: 50.2 | G14: =IF(C14=0,"—",F14/C14) | I14: =F14/D14-1
A15: Влада | B15: Август* | C15: 111.9 | D15: 74.3 | E15: =IF(C15=0,"—",D15/C15) | F15: 49 | G15: =IF(C15=0,"—",F15/C15) | I15: =F15/D15-1
A16: Татьяна | B16: Июнь | C16: 135.3 | D16: 115.9 | E16: =IF(C16=0,"—",D16/C16) | F16: 99 | G16: =IF(C16=0,"—",F16/C16) | H16: =AVERAGE(G16:G18) | I16: =F16/D16-1
A17: Татьяна | B17: Июль | C17: 143 | D17: 113.2 | E17: =IF(C17=0,"—",D17/C17) | F17: 96.1 | G17: =IF(C17=0,"—",F17/C17) | I17: =F17/D17-1
A18: Татьяна | B18: Август* | C18: 0 | D18: 0 | E18: =IF(C18=0,"—",D18/C18) | F18: 0 | G18: =IF(C18=0,"—",F18/C18) | I18: =F18/D18-1
A20: Клиника | B20: Июнь | C20: =C4+C7+C10+C13+C16 | D20: =D4+D7+D10+D13+D16 | E20: =IF(C20=0,"—",D20/C20) | F20: =F4+F7+F10+F13+F16 | G20: =IF(C20=0,"—",F20/C20) | H20: =AVERAGE(G20:G22)
A21: Клиника | B21: Июль | C21: =C5+C8+C11+C14+C17 | D21: =D5+D8+D11+D14+D17 | E21: =IF(C21=0,"—",D21/C21) | F21: =F5+F8+F11+F14+F17 | G21: =IF(C21=0,"—",F21/C21)
A22: Клиника | B22: Август* | C22: =C6+C9+C12+C15+C18 | D22: =D6+D9+D12+D15+D18 | E22: =IF(C22=0,"—",D22/C22) | F22: =F6+F9+F12+F15+F18 | G22: =IF(C22=0,"—",F22/C22)
A23: Клиника без Эльвиры | B23: Июнь | C23: =C4+C10+C13+C16 | D23: =D4+D10+D13+D16 | E23: =IF(C23=0,"—",D23/C23) | F23: =F4+F10+F13+F16 | G23: =IF(C23=0,"—",F23/C23) | H23: =AVERAGE(G23:G25)
A24: Клиника без Эльвиры | B24: Июль | C24: =C5+C11+C14+C17 | D24: =D5+D11+D14+D17 | E24: =IF(C24=0,"—",D24/C24) | F24: =F5+F11+F14+F17 | G24: =IF(C24=0,"—",F24/C24)
A25: Клиника без Эльвиры | B25: Август* | C25: =C6+C12+C15+C18 | D25: =D6+D12+D15+D18 | E25: =IF(C25=0,"—",D25/C25) | F25: =F6+F12+F15+F18 | G25: =IF(C25=0,"—",F25/C25)
A26: * Август — не закрытый месяц. Красным — строки, где «Записано» больше «Открыто» (>100% занятости) — у Эльвиры такое во всех трёх месяцах: её реальный календарь шире, чем отдаёт эндпоинт расписания YClients (вероятно, из-за нестандартного режима работы/дополнительных слотов, не отражённых в стандартном расписании). Это не ошибка расчёта — числовые % для неё не показатель, только татьяна/анна/александра/влада можно сравнивать напрямую.
A28: Татьяна — 0 в августе: похоже, в этом месяце её нет в расписании (не работает/на паузе) — стоит уточнить у клиники, не баг пайплайна.

Sheet Ёмкость клиники
A1: Ёмкость клиники — физический потолок и запас под план роста
A3: Параметры (жёлтые — можно менять)
A4: Часов работы клиники в день | B4: 10 | C4: ч | D4: 10:00-20:00
A5: Рабочих дней в месяце (оценка) | B5: 30 | C5: дн
A6: Кабинетов всего (одновременных клиентов максимум) | B6: 3 | C6: шт | D6: Косметолог гибко занимает любой свободный — лампу/оборудование можно передвинуть
A7: Лимит ЛЭ одновременно (1 аппарат) | B7: 1 | C7: шт
A8: Лимит массажа одновременно (1 кресло) | B8: 1 | C8: шт
A10: Потолок (часов/мес)
A11: Вся клиника (3 места) | B11: =$B$4*$B$5*$B$6
A12: ЛЭ (1 аппарат) | B12: =$B$4*$B$5*$B$7
A13: Массаж (1 кресло) | B13: =$B$4*$B$5*$B$8
A16: Текущая загрузка (факт, реально отработанные часы)
A17: Месяц | B17: Вся клиника, ч | C17: % от потолка (900ч) | D17: ЛЭ, ч | E17: % от потолка ЛЭ | F17: Массаж, ч | G17: % от потолка массажа
A18: Июнь | B18: 359.7 | C18: =B18/$B$11 | D18: 80.9 | E18: =D18/$B$12 | F18: 78.2 | G18: =F18/$B$13
A19: Июль | B19: 290 | C19: =B19/$B$11 | D19: 89.5 | E19: =D19/$B$12 | F19: 50.6 | G19: =F19/$B$13
A20: Август* | B20: 166.2 | C20: =B20/$B$11 | D20: 51.8 | E20: =D20/$B$12 | F20: 22.7 | G20: =F20/$B$13
A22: * Август — часы по состоянию на 25.08 (неполный месяц), «Вся клиника» — сумма реально отработанных часов по всем 6 мастерам (включая Анжелу).
A24: Сколько часов нужно под план роста «Остальные» +10%/мес (сен-дек)
A25: ₽/час у «Остальных» (среднее июнь-июль) | B25: =(740057+664344)/(263.9+213)
A27: Месяц | B27: План «Остальные», ₽ | C27: Нужно часов «Остальным» | D27: + часы Эльвиры (плоско ~86 ч) | E27: ИТОГО часов клиники нужно | F27: % от потолка (900ч)
A28: Сентябрь | B28: ='ПРОГНОЗ'!F4 | C28: =B28/$B$25 | D28: 86 | E28: =C28+D28 | F28: =E28/$B$11
A29: Октябрь | B29: ='ПРОГНОЗ'!J4 | C29: =B29/$B$25 | D29: 86 | E29: =C29+D29 | F29: =E29/$B$11
A30: Ноябрь | B30: ='ПРОГНОЗ'!N4 | C30: =B30/$B$25 | D30: 86 | E30: =C30+D30 | F30: =E30/$B$11
A31: Декабрь | B31: ='ПРОГНОЗ'!R4 | C31: =B31/$B$25 | D31: 86 | E31: =C31+D31 | F31: =E31/$B$11
A33: Вывод: даже в декабре при плане роста «Остальных» +10%/мес суммарная загрузка клиники не подходит близко к потолку в 900 ч/мес (см. % от потолка выше) — физических ограничений по кабинетам в ближайшие 4 месяца не видно. Отдельно стоит смотреть личную загрузку каждого мастера (сколько часов лично готовы работать) — это не про кабинеты, это про людей, см. лист «Загрузка мастеров».
A36: Сколько стоит час у каждого мастера + среднее время на клиента (июнь-июль)
A37: Мастер | B37: Выручка услуг, ₽ (июнь-июль) | C37: Отработано часов | D37: ₽/час | E37: Визитов | F37: Среднее время на клиента, мин
A38: Эльвира | B38: 2375383 | C38: 172.8 | D38: =B38/C38 | E38: 234 | F38: =C38*60/E38
A39: Татьяна | B39: 807635 | C39: 195.1 | D39: =B39/C39 | E39: 183 | F39: =C39*60/E39
A40: Анна | B40: 281350 | C40: 85.9 | D40: =B40/C40 | E40: 62 | F40: =C40*60/E40 | G40: в сравнении с Таней - дорогой спец
A41: Александра | B41: 150859 | C41: 72.2 | D41: =B41/C41 | E41: 63 | F41: =C41*60/E41
A42: Влада | B42: 164557 | C42: 123.7 | D42: =B42/C42 | E42: 107 | F42: =C42*60/E42 | G42: поднимать чек
A45: Эффективность роста: сколько денег дают ОДИНАКОВЫЕ +20 доп. часов у разных мастеров
A46: Мастер | B46: ₽/час | C46: +20 часов сверх текущего дают, ₽ | D46: Ранг по эффективности
A47: Татьяна | B47: =D39 | C47: =D39*20 | D47: =RANK(B47,$B$47:$B$50)
A48: Анна | B48: =D40 | C48: =D40*20 | D48: =RANK(B48,$B$47:$B$50)
A49: Александра | B49: =D41 | C49: =D41*20 | D49: =RANK(B49,$B$47:$B$50)
A50: Влада | B50: =D42 | C50: =D42*20 | D50: =RANK(B50,$B$47:$B$50)
A52: Смысл: если план роста «Остальных» распределять не поровну, а в первую очередь давать доп. часы Татьяне (4 140 ₽/час) и Анне (3 275 ₽/час), а не Владе (1 330 ₽/час) — та же выручка достигается МЕНЬШИМ количеством часов (то есть быстрее и с меньшей нагрузкой на команду), либо те же часы дают больше денег. Компромисс: Александра и Влада тогда растут медленнее — если для тебя важно развивать их загрузку в частности (не только общую выручку клиники), это стоит явно решить, а не просто гнаться за максимальной эффективностью ₽/час.

Sheet ПРОГНОЗ
A1: ТЕКУЩАЯ СИТУАЦИЯ | B1: Точка А (среднее июнь-июль) | E1: СЕНТЯБРЬ | F1: ТОЧКА Б (цель — декабрь 2026, план роста 10%/мес) | I1: ОКТЯБРЬ | J1: ТОЧКА Б (цель — декабрь 2026, план роста 10%/мес) | M1: НОЯБРЬ | N1: ТОЧКА Б (цель — декабрь 2026, план роста 10%/мес) | Q1: ДЕКАБРЬ | R1: ТОЧКА Б (цель — декабрь 2026, план роста 10%/мес)
A2: ВЫРУЧКА | B2: 2403436 | E2: ВЫРУЧКА | F2: 2300000 | I2: ВЫРУЧКА | J2: 2300000 | M2: ВЫРУЧКА | N2: 2300000 | Q2: ВЫРУЧКА | R2: 2300000
A3: - Эльвира | B3: =B2-B4 | E3: - Эльвира | F3: =F2-F4 | I3: - Эльвира | J3: =J2-J4 | M3: - Эльвира | N3: =N2-N4 | Q3: - Эльвира | R3: =R2-R4
A4: - Остальные | B4: 960140 | E4: - Остальные | F4: 1000000 | I4: - Остальные | J4: =F4*1.1 | M4: - Остальные | N4: =J4*1.1 | Q4: - Остальные | R4: =N4*1.1
A5: кол-во клиентов в месяц | B5: 198 | E5: кол-во клиентов в месяц | F5: 190 | I5: кол-во клиентов в месяц | J5: 190 | M5: кол-во клиентов в месяц | N5: 190 | Q5: кол-во клиентов в месяц | R5: 190
B7: ₽ | C7: % | F7: ₽ | G7: % | J7: ₽ | K7: % | N7: ₽ | O7: % | R7: ₽ | S7: %
A8: Постоянные расходы ВСЕГО | B8: =SUM(B9:B12)+B13+B18+B19 | C8: =B8/$B$2 | E8: Постоянные расходы ВСЕГО | F8: =SUM(F9:F12)+F13+F18+F19 | G8: =F8/$F$2 | I8: Постоянные расходы ВСЕГО | J8: =SUM(J9:J12)+J13+J18+J19 | K8: =J8/$F$2 | M8: Постоянные расходы ВСЕГО | N8: =SUM(N9:N12)+N13+N18+N19 | O8: =N8/$F$2 | Q8: Постоянные расходы ВСЕГО | R8: =SUM(R9:R12)+R13+R18+R19 | S8: =R8/$F$2
A9: Аренда и содержание помещения | B9: 81980 | C9: =B9/$B$2 | E9: Аренда и содержание помещения | F9: 81980 | G9: =F9/$F$2 | I9: Аренда и содержание помещения | J9: 81980 | K9: =J9/$F$2 | M9: Аренда и содержание помещения | N9: 81980 | O9: =N9/$F$2 | Q9: Аренда и содержание помещения | R9: 81980 | S9: =R9/$F$2
A10: Связь и интернет (IT-сервисы) | B10: 41410 | C10: =B10/$B$2 | E10: Связь и интернет (IT-сервисы) | F10: 15000 | G10: =F10/$F$2 | I10: Связь и интернет (IT-сервисы) | J10: 15000 | K10: =J10/$F$2 | M10: Связь и интернет (IT-сервисы) | N10: 15000 | O10: =N10/$F$2 | Q10: Связь и интернет (IT-сервисы) | R10: 15000 | S10: =R10/$F$2
A11: Хоз. и санитарные нужды | B11: 62567 | C11: =B11/$B$2 | E11: Хоз. и санитарные нужды | F11: 62567 | G11: =F11/$F$2 | I11: Хоз. и санитарные нужды | J11: 62567 | K11: =J11/$F$2 | M11: Хоз. и санитарные нужды | N11: 62567 | O11: =N11/$F$2 | Q11: Хоз. и санитарные нужды | R11: 62567 | S11: =R11/$F$2
A12: Банковское обслуживание, юр., бухгалтерия | B12: 35164 | C12: =B12/$B$2 | E12: Банковское обслуживание, юр., бухгалтерия | F12: 35164 | G12: =F12/$F$2 | I12: Банковское обслуживание, юр., бухгалтерия | J12: 35164 | K12: =J12/$F$2 | M12: Банковское обслуживание, юр., бухгалтерия | N12: 35164 | O12: =N12/$F$2 | Q12: Банковское обслуживание, юр., бухгалтерия | R12: 35164 | S12: =R12/$F$2
A13: ФОТ офиса | B13: =SUM(B14:B17) | C13: =B13/$B$2 | E13: ФОТ офиса | F13: =SUM(F14:F17) | G13: =F13/$F$2 | I13: ФОТ офиса | J13: =SUM(J14:J17) | K13: =J13/$F$2 | M13: ФОТ офиса | N13: =SUM(N14:N17) | O13: =N13/$F$2 | Q13: ФОТ офиса | R13: =SUM(R14:R17) | S13: =R13/$F$2
A14: СЕО | B14: 52121 | C14: =B14/$B$2 | E14: СЕО | F14: 52121 | G14: =F14/$F$2 | I14: СЕО | J14: 52121 | K14: =J14/$F$2 | M14: СЕО | N14: 52121 | O14: =N14/$F$2 | Q14: СЕО | R14: 52121 | S14: =R14/$F$2
A15: Управляющий | B15: 60000 | C15: =B15/$B$2 | E15: Управляющий | F15: ='КПИ управляющей'!$B$4 | G15: =F15/$F$2 | I15: Управляющий | J15: ='КПИ управляющей'!$B$4 | K15: =J15/$F$2 | M15: Управляющий | N15: ='КПИ управляющей'!$B$4 | O15: =N15/$F$2 | Q15: Управляющий | R15: ='КПИ управляющей'!$B$4 | S15: =R15/$F$2
A16: Администраторы | B16: 60000 | C16: =B16/$B$2 | E16: Администраторы | F16: ='КПИ администраторов'!D26+'КПИ администраторов'!D27 | G16: =F16/$F$2 | I16: Администраторы | J16: ='КПИ администраторов'!D28+'КПИ администраторов'!D29 | K16: =J16/$F$2 | M16: Администраторы | N16: ='КПИ администраторов'!D30+'КПИ администраторов'!D31 | O16: =N16/$F$2 | Q16: Администраторы | R16: ='КПИ администраторов'!D32+'КПИ администраторов'!D33 | S16: =R16/$F$2
A17: Прочее (страховые, юр.услуги, бухгалтерия, проектные) | B17: 28800 | C17: =B17/$B$2 | E17: Прочее (страховые, юр.услуги, бухгалтерия, проектные) | F17: 28800 | G17: =F17/$F$2 | I17: Прочее (страховые, юр.услуги, бухгалтерия, проектные) | J17: 28800 | K17: =J17/$F$2 | M17: Прочее (страховые, юр.услуги, бухгалтерия, проектные) | N17: 28800 | O17: =N17/$F$2 | Q17: Прочее (страховые, юр.услуги, бухгалтерия, проектные) | R17: 28800 | S17: =R17/$F$2
A18: Обучение и HR | B18: 54169 | C18: =B18/$B$2 | E18: Обучение и HR | F18: 10000 | G18: =F18/$F$2 | I18: Обучение и HR | J18: 10000 | K18: =J18/$F$2 | M18: Обучение и HR | N18: 10000 | O18: =N18/$F$2 | Q18: Обучение и HR | R18: 10000 | S18: =R18/$F$2
A19: Прочие операционные расходы | B19: 12806 | C19: =B19/$B$2 | E19: Прочие операционные расходы | F19: 12806 | G19: =F19/$F$2 | I19: Прочие операционные расходы | J19: 12806 | K19: =J19/$F$2 | M19: Прочие операционные расходы | N19: 12806 | O19: =N19/$F$2 | Q19: Прочие операционные расходы | R19: 12806 | S19: =R19/$F$2
A21: Переменные расходы ВСЕГО | B21: =B22+B33+B40+B44+B36 | C21: =B21/$B$2 | E21: Переменные расходы ВСЕГО | F21: =F22+F33+F40+F44+F36 | G21: =F21/$F$2 | I21: Переменные расходы ВСЕГО | J21: =J22+J33+J40+J44+J36 | K21: =J21/$F$2 | M21: Переменные расходы ВСЕГО | N21: =N22+N33+N40+N44+N36 | O21: =N21/$F$2 | Q21: Переменные расходы ВСЕГО | R21: =R22+R33+R40+R44+R36 | S21: =R21/$F$2
A22: Переменные расходы на маркетинг | B22: =SUM(B23:B31) | C22: =B22/$B$2 | E22: Переменные расходы на маркетинг | F22: =SUM(F23:F31) | G22: =F22/$F$2 | I22: Переменные расходы на маркетинг | J22: =SUM(J23:J31) | K22: =J22/$F$2 | M22: Переменные расходы на маркетинг | N22: =SUM(N23:N31) | O22: =N22/$F$2 | Q22: Переменные расходы на маркетинг | R22: =SUM(R23:R31) | S22: =R22/$F$2
A23: ЗП маркетолога | B23: 81683 | C23: =B23/$B$2 | E23: ЗП маркетолога | F23: 65000 | G23: =F23/$F$2 | I23: ЗП маркетолога | J23: 65000 | K23: =J23/$F$2 | M23: ЗП маркетолога | N23: 65000 | O23: =N23/$F$2 | Q23: ЗП маркетолога | R23: 65000 | S23: =R23/$F$2
A24: ЗП СММ | E24: ЗП СММ | F24: 35000 | G24: =F24/$F$2 | I24: ЗП СММ | J24: 35000 | K24: =J24/$F$2 | M24: ЗП СММ | N24: 35000 | O24: =N24/$F$2 | Q24: ЗП СММ | R24: 35000 | S24: =R24/$F$2
A25: ЗП трафиктолог | E25: ЗП трафиктолог | F25: 0 | G25: =F25/$F$2 | I25: ЗП трафиктолог | J25: 0 | K25: =J25/$F$2 | M25: ЗП трафиктолог | N25: 0 | O25: =N25/$F$2 | Q25: ЗП трафиктолог | R25: 0 | S25: =R25/$F$2
A26: ЗП Директолог | E26: ЗП Директолог | F26: 0 | G26: =F26/$F$2 | I26: ЗП Директолог | J26: 0 | K26: =J26/$F$2 | M26: ЗП Директолог | N26: 0 | O26: =N26/$F$2 | Q26: ЗП Директолог | R26: 0 | S26: =R26/$F$2
A27: Площадки-агрегаторы (Яндекс, 2GIS, Zoon) | B27: 26034 | C27: =B27/$B$2 | E27: Площадки-агрегаторы (Яндекс, 2GIS, Zoon) | F27: 0 | G27: =F27/$F$2 | I27: Площадки-агрегаторы (Яндекс, 2GIS, Zoon) | J27: 0 | K27: =J27/$F$2 | M27: Площадки-агрегаторы (Яндекс, 2GIS, Zoon) | N27: 0 | O27: =N27/$F$2 | Q27: Площадки-агрегаторы (Яндекс, 2GIS, Zoon) | R27: 0 | S27: =R27/$F$2
A28: Яндекс.Директ бюджет | E28: Яндекс.Директ бюджет | F28: 0 | G28: =F28/$F$2 | I28: Яндекс.Директ бюджет | J28: 0 | K28: =J28/$F$2 | M28: Яндекс.Директ бюджет | N28: 0 | O28: =N28/$F$2 | Q28: Яндекс.Директ бюджет | R28: 0 | S28: =R28/$F$2
A29: Таргет бюджет | E29: Таргет бюджет | F29: 0 | G29: =F29/$F$2 | I29: Таргет бюджет | J29: 0 | K29: =J29/$F$2 | M29: Таргет бюджет | N29: 0 | O29: =N29/$F$2 | Q29: Таргет бюджет | R29: 0 | S29: =R29/$F$2
A30: Блогеры | E30: Блогеры | F30: 0 | G30: =F30/$F$2 | I30: Блогеры | J30: 0 | K30: =J30/$F$2 | M30: Блогеры | N30: 0 | O30: =N30/$F$2 | Q30: Блогеры | R30: 0 | S30: =R30/$F$2
A31: Дизайн, полиграфия, контент | B31: 19946 | C31: =B31/$B$2 | E31: Дизайн, полиграфия, контент | F31: 10000 | G31: =F31/$F$2 | I31: Дизайн, полиграфия, контент | J31: 10000 | K31: =J31/$F$2 | M31: Дизайн, полиграфия, контент | N31: 10000 | O31: =N31/$F$2 | Q31: Дизайн, полиграфия, контент | R31: 10000 | S31: =R31/$F$2
A33: Переменные расходы на мастеров (комиссия от услуг и продажа абонементов, товаров) | B33: =SUM(B34) | C33: =B33/$B$2 | E33: Переменные расходы на мастеров (комиссия от услуг и продажа абонементов, товаров) | F33: =SUM(F34) | G33: =F33/$F$2 | I33: Переменные расходы на мастеров (комиссия от услуг и продажа абонементов, товаров) | J33: =SUM(J34) | K33: =J33/$F$2 | M33: Переменные расходы на мастеров (комиссия от услуг и продажа абонементов, товаров) | N33: =SUM(N34) | O33: =N33/$F$2 | Q33: Переменные расходы на мастеров (комиссия от услуг) | R33: =SUM(R34) | S33: =R33/$F$2
A34: ЗП мастеров | B34: 618658 | C34: =B34/$B$2 | E34: ЗП мастеров | F34: 592000 | G34: =F34/$F$2 | I34: ЗП мастеров | J34: 592000 | K34: =J34/$F$2 | M34: ЗП мастеров | N34: 592000 | O34: =N34/$F$2 | Q34: ЗП мастеров | R34: 592000 | S34: =R34/$F$2
A36: Переменные расходы на кпи (зависит от плана) | B36: =SUM(B37:B38) | C36: =B36/$B$2 | E36: Переменные расходы на мастеров (комиссия от услуг) | F36: =SUM(F37:F38) | G36: =F36/$F$2 | I36: Переменные расходы на мастеров (комиссия от услуг) | J36: =SUM(J37:J38) | K36: =J36/$F$2 | M36: Переменные расходы на мастеров (комиссия от услуг) | N36: =SUM(N37:N38) | O36: =N36/$F$2 | Q36: Переменные расходы на мастеров (комиссия от услуг) | R36: =SUM(R37:R38) | S36: =R36/$F$2
A37: Управляющий кпи | E37: Управляющий кпи | F37: ='КПИ управляющей'!E14 | I37: Управляющий кпи | J37: ='КПИ управляющей'!E15 | M37: Управляющий кпи | N37: =SUM('КПИ управляющей'!E16) | O37: =N37/$F$2 | Q37: Управляющий кпи | R37: =SUM('КПИ управляющей'!E17) | S37: =R37/$F$2
A38: Администраторы кпи | E38: Администраторы кпи | F38: =SUM('КПИ администраторов'!M26:M27) | I38: Администраторы кпи | J38: =SUM('КПИ администраторов'!M28:M29) | M38: Администраторы кпи | N38: =SUM('КПИ администраторов'!M30:M31) | O38: =N38/$F$2 | Q38: Администраторы кпи | R38: =SUM('КПИ администраторов'!M32:M33) | S38: =R38/$F$2
A40: Переменные расходы на материалы | B40: =SUM(B41:B42) | C40: =B40/$B$2 | E40: Переменные расходы на материалы | F40: =SUM(F41:F42) | G40: =F40/$F$2 | I40: Переменные расходы на материалы | J40: =SUM(J41:J42) | K40: =J40/$F$2 | M40: Переменные расходы на материалы | N40: =SUM(N41:N42) | O40: =N40/$F$2 | Q40: Переменные расходы на материалы | R40: =SUM(R41:R42) | S40: =R40/$F$2
A41: Расходники и препараты (прямые) | B41: 566752 | C41: =B41/$B$2 | E41: Расходники и препараты (прямые) | F41: 542000 | G41: =F41/$F$2 | I41: Расходники и препараты (прямые) | J41: 542000 | K41: =J41/$F$2 | M41: Расходники и препараты (прямые) | N41: 542000 | O41: =N41/$F$2 | Q41: Расходники и препараты (прямые) | R41: 542000 | S41: =R41/$F$2
A42: Закупка косметики на продажу (сглажено) | B42: 346599 | C42: =B42/$B$2 | E42: Закупка косметики на продажу (сглажено) | F42: 134438 | G42: =F42/$F$2 | I42: Закупка косметики на продажу (сглажено) | J42: 134438 | K42: =J42/$F$2 | M42: Закупка косметики на продажу (сглажено) | N42: 134438 | O42: =N42/$F$2 | Q42: Закупка косметики на продажу (сглажено) | R42: 134438 | S42: =R42/$F$2
A44: Другие переменные | B44: =SUM(B45) | C44: =B44/$B$2 | E44: Другие переменные | F44: =SUM(F45) | G44: =F44/$F$2 | I44: Другие переменные | J44: =SUM(J45) | K44: =J44/$F$2 | M44: Другие переменные | N44: =SUM(N45) | O44: =N44/$F$2 | Q44: Другие переменные | R44: =SUM(R45) | S44: =R44/$F$2
A45: Налоги (на прибыль + на ФОТ) | B45: 92014 | C45: =B45/$B$2 | E45: Налоги (на прибыль + на ФОТ) | F45: 88000 | G45: =F45/$F$2 | I45: Налоги (на прибыль + на ФОТ) | J45: 88000 | K45: =J45/$F$2 | M45: Налоги (на прибыль + на ФОТ) | N45: 88000 | O45: =N45/$F$2 | Q45: Налоги (на прибыль + на ФОТ) | R45: 88000 | S45: =R45/$F$2
A48: ВЫРУЧКА | B48: =B2 | E48: ВЫРУЧКА | F48: =F2 | I48: ВЫРУЧКА | J48: =J2 | M48: ВЫРУЧКА | N48: =N2 | Q48: ВЫРУЧКА | R48: =R2
...

Sheet КПИ администраторов
A1: КПИ администраторов — калькулятор
A3: Правила начисления (жёлтые — можно менять) | C3: Сейчас
A4: Фикс за смену | B4: 2000 | C4: 2500 | D4: - чистота - подтверждения записей - корректное ведение срм и фин таблицы - своевременное выполнение задач от рук-ва
A6: Загрузка специалистов (клиника, за месяц), на всех | C6: Сейчас | D6: сомнения
A7: < 55% | B7: 0 | C7: 56,% с Эльвирой 48% без Эльвиры
A8: 55-75% | B8: 0
A9: от 76% | B9: 0
A11: План по выручке (Остальные мастера, без Эльвиры), на всех | C11: Сейчас | D11: Вариант 2: за продажу абонементов, косметики, депозиты. Но это сложнее считать
A12: ниже 85% | B12: 0 | C12: 960140
A13: 85-99% | B13: 10000 | E13: =B13/388 | G13: =1000000*85%
A14: 100% и выше | B14: 26000 | E14: =B14/388
A16: Отзывы 4+ на картах (₽ за штуку, по количеству за месяц), на всех | C16: Сейчас
A17: до 7 шт | B17: 0 | C17: март - 1, 6 апрель - 0, май - 0, 3 июнь - 1, 19 июль - 4, 22 авг - 0, 4
A18: 8-15 шт | B18: 0 | D18: 250
A19: от 16 шт | B19: 0 | D19: 300
I20: ср за визит | J20: сбп | K20: карта
A21: Оплата по QR-коду, ₽ за шт, отслеживание на смену | B21: 0 | C21: июнь - 20 июль - 46 Авг на 21.08 - 31 | D21: Сумма маленькая, не интересно, а нам из-за низкого ср. чека, выше делать невыгодно | I21: 7285 | J21: =I21*0.4% | K21: =I21*0.9% | L21: =K21-J21
A24: Расчёт по месяцам
A25: Администратор | B25: Месяц | C25: Смены | D25: Фикс, ₽ | E25: Загрузка специалистов, % | F25: Бонус загрузка, ₽ | G25: % плана по выручке (Остальные) | H25: Бонус план, ₽ | I25: Отзывы, шт | J25: Бонус отзывы, ₽ | K25: QR-платежи, шт | L25: Бонус QR, ₽ | M25: ИТОГО Бонус | N25: ИТОГО, ₽
A26: Администратор 1 | B26: Сентябрь | C26: 15 | D26: =C26*$B$4 | E26: 0.6 | F26: =IF(E26<0.55,$B$7,IF(E26<=0.75,$B$8,$B$9))/2 | G26: 0.87 | H26: =IF(G26<0.85,$B$12,IF(G26<1,$B$13,$B$14))/2 | I26: 10 | J26: =IF(I26="",0,I26*IF(I26<8,$B$17,IF(I26<=15,$B$18,$B$19)))/2 | K26: 25 | L26: =IF(K26="",0,K26*$B$21) | M26: =F26+H26+J26+L26 | N26: =D26+F26+H26+J26+L26
A27: Администратор 2 | B27: Сентябрь | C27: 15 | D27: =C27*$B$4 | F27: =IF(E26<0.55,$B$7,IF(E26<=0.75,$B$8,$B$9))/2 | H27: =IF(G26<0.85,$B$12,IF(G26<1,$B$13,$B$14))/2 | J27: =IF(I26="",0,I26*IF(I26<8,$B$17,IF(I26<=15,$B$18,$B$19)))/2 | K27: 15 | L27: =IF(K27="",0,K27*$B$21) | M27: =F27+H27+J27+L27 | N27: =D27+F27+H27+J27+L27
A28: Администратор 1 | B28: Октябрь | C28: 15 | D28: =C28*$B$4 | E28: 0.6 | F28: =IF(E28<0.55,$B$7,IF(E28<=0.75,$B$8,$B$9))/2 | G28: 1 | H28: =IF(G28<0.85,$B$12,IF(G28<1,$B$13,$B$14))/2 | I28: 10 | J28: =IF(I28="",0,I28*IF(I28<8,$B$17,IF(I28<=15,$B$18,$B$19)))/2 | K28: 17 | L28: =IF(K28="",0,K28*$B$21) | M28: =F28+H28+J28+L28 | N28: =D28+F28+H28+J28+L28
A29: Администратор 2 | B29: Октябрь | C29: 16 | D29: =C29*$B$4 | F29: =IF(E28<0.55,$B$7,IF(E28<=0.75,$B$8,$B$9))/2 | H29: =IF(G28<0.85,$B$12,IF(G28<1,$B$13,$B$14))/2 | J29: =IF(I28="",0,I28*IF(I28<8,$B$17,IF(I28<=15,$B$18,$B$19)))/2 | K29: =45-K28 | L29: =IF(K29="",0,K29*$B$21) | M29: =F29+H29+J29+L29 | N29: =D29+F29+H29+J29+L29
A30: Администратор 1 | B30: Ноябрь | C30: 15 | D30: =C30*$B$4 | E30: 0.77 | F30: =IF(E30<0.55,$B$7,IF(E30<=0.75,$B$8,$B$9))/2 | G30: 1.05 | H30: =IF(G30<0.85,$B$12,IF(G30<1,$B$13,$B$14))/2 | I30: 20 | J30: =IF(I30="",0,I30*IF(I30<8,$B$17,IF(I30<=15,$B$18,$B$19)))/2 | K30: 25 | L30: =IF(K30="",0,K30*$B$21) | M30: =F30+H30+J30+L30 | N30: =D30+F30+H30+J30+L30
A31: Администратор 2 | B31: Ноябрь | C31: 15 | D31: =C31*$B$4 | F31: =IF(E30<0.55,$B$7,IF(E30<=0.75,$B$8,$B$9))/2 | H31: =IF(G30<0.85,$B$12,IF(G30<1,$B$13,$B$14))/2 | J31: =IF(I30="",0,I30*IF(I30<8,$B$17,IF(I30<=15,$B$18,$B$19)))/2 | K31: 25 | L31: =IF(K31="",0,K31*$B$21) | M31: =F31+H31+J31+L31 | N31: =D31+F31+H31+J31+L31
A32: Администратор 1 | B32: Декабрь | C32: 15 | D32: =C32*$B$4 | E32: 0.77 | F32: =IF(E32<0.55,$B$7,IF(E32<=0.75,$B$8,$B$9))/2 | G32: 1.05 | H32: =IF(G32<0.85,$B$12,IF(G32<1,$B$13,$B$14))/2 | I32: 20 | J32: =IF(I32="",0,I32*IF(I32<8,$B$17,IF(I32<=15,$B$18,$B$19)))/2 | K32: 30 | L32: =IF(K32="",0,K32*$B$21) | M32: =F32+H32+J32+L32 | N32: =D32+F32+H32+J32+L32
A33: Администратор 2 | B33: Декабрь | C33: 15 | D33: =C33*$B$4 | F33: =IF(E32<0.55,$B$7,IF(E32<=0.75,$B$8,$B$9))/2 | H33: =IF(G32<0.85,$B$12,IF(G32<1,$B$13,$B$14))/2 | J33: =IF(I32="",0,I32*IF(I32<8,$B$17,IF(I32<=15,$B$18,$B$19)))/2 | K33: 30 | L33: =IF(K33="",0,K33*$B$21) | M33: =F33+H33+J33+L33 | N33: =D33+F33+H33+J33+L33
A34: «Загрузка специалистов» и «% плана по выручке» — общеклиничные показатели за месяц (одинаковы для обоих администраторов в один месяц, не считаю раздельно по сменам, потому что загрузка/выручка не разбита по тому, кто в этот день на смене). Загрузка = реально отработанные часы (статус «Пришёл») / открытые по расписанию часы, по всем мастерам вместе. Из-за известного расхождения по Эльвире (её факт расписания шире, чем видит API) цифра может быть немного занижена — если заметишь явно нелогичный % в какой-то месяц, скажи, пересчитаю аккуratнее. | M34: =F34+H34+J34+L34
A36: «План по выручке» = факт выручки «Остальных» мастеров (без Эльвиры) / база 960 140 ₽ (среднее июнь-июль) — с сентября план начинает расти на 10%/мес по модели, тогда эта база уже не будет константой, а будет браться с листа «ПРОГНОЗ»/плана — скажи, когда дойдём до сентября, пересчитаю на актуальный план того месяца.
A38: Жёлтые ячейки — впиши: смены, кол-во отзывов, кол-во QR-платежей на каждого администратора по месяцам.

Sheet КПИ управляющей
A1: КПИ управляющей — калькулятор
A3: Правила начисления (жёлтые — можно менять) | C3: Сейчас
A4: Фикс | B4: 50000 | C4: 50000
A6: КПИ от плана продаж (выручка «Остальных» мастеров, без Эльвиры) | C6: Сейчас
A7: ниже 85% плана | B7: 0 | C7: 0.02
A8: 85-99% плана | B8: 0.01
A9: 100% плана и выше | B9: 0.02
A12: Расчёт по месяцам
A13: Месяц | B13: Выручка «Остальные», ₽ | C13: % плана | D13: Ставка КПИ | E13: КПИ, ₽ | F13: Фикс, ₽ | G13: ИТОГО, ₽ | I13: Сейчас
A14: Сентябрь | B14: =C14*B22 | C14: 0.9 | D14: =IF(C14<0.85,$B$7,IF(C14<1,$B$8,$B$9)) | E14: =B14*D14 | F14: =$B$4 | G14: =E14+F14 | I14: =C4+C7*B14
A15: Октябрь | B15: =C15*B23 | C15: 0.9 | D15: =IF(C15<0.85,$B$7,IF(C15<1,$B$8,$B$9)) | E15: =B15*D15 | F15: =$B$4 | G15: =E15+F15 | I15: =C4+C7*B15
A16: Ноябрь | B16: =C16*B24 | C16: 1.05 | D16: =IF(C16<0.85,$B$7,IF(C16<1,$B$8,$B$9)) | E16: =B16*D16 | F16: =$B$4 | G16: =E16+F16 | I16: =C4+C7*B16
A17: Декабрь | B17: =C17*B25 | C17: 1.15 | D17: =IF(C17<0.85,$B$7,IF(C17<1,$B$8,$B$9)) | E17: =B17*D17 | F17: =$B$4 | G17: =E17+F17 | I17: =C4+C7*B17
A19: «План» = база 960 140 ₽ (среднее июнь-июль) — с сентября будет расти на 10%/мес по модели с листа «ПРОГНОЗ», тогда обновлю базу на актуальный план того месяца, а не константу.
A21: Месяц | B21: ПЛАН продаж
A22: Сентябрь | B22: =960140*1.1
A23: Октябрь | B23: =B22*1.1
A24: Ноябрь | B24: =B23*1.1
A25: Декабрь | B25: =B24*1.1

Sheet КПИ мастеров
A1: КПИ мастеров — дополнительный бонус сверх обычной комиссии (см. лист «Эльвира vs Остальные»)
A3: Правила начисления (жёлтые — можно менять)
A4: % от продаж косметики/абонементов/депозитов | B4: 0.05
A5: Бонус за кейс (₽ за штуку) | B5: 3000
A6: За отзыв мастеру | B6: 200
A8: Расчёт по месяцам
A9: Мастер | B9: Месяц | C9: Продажи космметики/абонементов/депозитов, ₽ | D9: Бонус 5%, ₽ | E9: Кейсы, шт | F9: Бонус за кейсы, ₽ | G9: ИТОГО доп. бонус, ₽
A10: Эльвира Аминева | B10: Май | C10: 142681 | D10: =5%*C10 | F10: =IF(E10="",0,E10*$B$5) | G10: =D10+F10
A11: Эльвира Аминева | B11: Июнь | C11: 205510 | D11: =C11*$B$4 | F11: =IF(E11="",0,E11*$B$5) | G11: =D11+F11
A12: Эльвира Аминева | B12: Июль | C12: 179370 | D12: =C12*$B$4 | F12: =IF(E12="",0,E12*$B$5) | G12: =D12+F12
A13: Татьяна | B13: Май | C13: 19753 | D13: =C13*$B$4 | F13: =IF(E13="",0,E13*$B$5) | G13: =D13+F13
A14: Татьяна | B14: Июнь | C14: 18970 | D14: =C14*$B$4 | F14: =IF(E14="",0,E14*$B$5) | G14: =D14+F14
A15: Татьяна | B15: Июль | C15: 47710 | D15: =C15*$B$4 | F15: =IF(E15="",0,E15*$B$5) | G15: =D15+F15
A16: Анна | B16: Май | C16: 39170 | D16: =C16*$B$4 | F16: =IF(E16="",0,E16*$B$5) | G16: =D16+F16
A17: Анна | B17: Июнь | C17: 49250 | D17: =C17*$B$4 | F17: =IF(E17="",0,E17*$B$5) | G17: =D17+F17
A18: Анна | B18: Июль | C18: 19870 | D18: =C18*$B$4 | F18: =IF(E18="",0,E18*$B$5) | G18: =D18+F18
A19: Александра | B19: Май | C19: 18900 | D19: =C19*$B$4 | F19: =IF(E19="",0,E19*$B$5) | G19: =D19+F19
A20: Александра | B20: Июнь | C20: 18900 | D20: =C20*$B$4 | F20: =IF(E20="",0,E20*$B$5) | G20: =D20+F20
A21: Александра | B21: Июль | C21: 18900 | D21: =C21*$B$4 | F21: =IF(E21="",0,E21*$B$5) | G21: =D21+F21
A22: Влада | B22: Май | C22: 4810 | D22: =C22*$B$4 | F22: =IF(E22="",0,E22*$B$5) | G22: =D22+F22
... A24: Влада | B24: Июль | C24: 0 | D24: =C24*$B$4 | F24: =IF(E24="",0,E24*$B$5) | G24: =D24+F24
A26: Продажи космметики/абонементов/депозитов — из транзакций «Продажа товаров»/«Продажа абонементов»/«Пополнение счёта», привязанных к визиту этого мастера (та же логика привязки, что и в разделе «Товары» на дашборде). Это ДОПОЛНИТЕЛЬНЫЙ бонус — не включает обычную комиссию мастера за услуги (см. лист «Эльвира vs Остальные» и «ПРОГНОЗ»). Кейсы — впиши количество вручную в жёлтые ячейки, в CRM это не фиксируется.

Sheet Косметика — методология
A1: Закупка косметики на продажу — открытый методологический вопрос
A3: Проблема | B3: Сейчас в П&Л закупка списывается целиком в месяц оплаты поставщику, но это запас на несколько месяцев продаж вперёд — из-за этого П&Л скачет (март/июнь/июль искажены разовыми крупными закупками).
A5: Что я сделала для модели | B5: Взяла ИТОГО закупок янв-авг (1 075 507 ₽) / 8 месяцев = 134 438 ₽/мес как сглаженную оценку — это ВРЕМЕННОЕ решение для прогноза, не бухгалтерская правильная амортизация.
A7: Как сделать правильно | B7: Нужно знать остатки товара на складе на конец каждого месяца (у меня есть текущий снимок остатков в дашборде ЭЛАМИ, но не исторический по месяцам) — тогда можно считать реальный расход = закупки + начальный остаток − конечный остаток, а не по факту оплаты поставщику.
A9: Что нужно от тебя | B9: Скажи: (а) устраивает ли сглаживание по среднему как временное решение, (б) можно ли начать фиксировать остатки на конец каждого месяца, чтобы перейти на правильный метод.
